{
  "error": "[Errno 122] Disk quota exceeded",
  "traceback": "Traceback (most recent call last):\n  File \"/data/leuven/371/vsc37132/miniconda3/envs/qtype-eval/lib/python3.9/site-packages/torch/serialization.py\", line 850, in save\n    _save(\n  File \"/data/leuven/371/vsc37132/miniconda3/envs/qtype-eval/lib/python3.9/site-packages/torch/serialization.py\", line 1114, in _save\n    zip_file.write_record(name, storage, num_bytes)\nRuntimeError: [enforce fail at inline_container.cc:778] . PytorchStreamWriter failed writing file data/97: file write failed\n\nDuring handling of the above exception, another exception occurred:\n\nTraceback (most recent call last):\n  File \"/vsc-hard-mounts/leuven-data/371/vsc37132/qtype-eval/src/experiments/run_experiment.py\", line 381, in run_lm_experiment\n    results = trainer.train(\n  File \"/vsc-hard-mounts/leuven-data/371/vsc37132/qtype-eval/src/training/lm_trainer.py\", line 161, in train\n    torch.save(self.model.state_dict(), os.path.join(self.output_dir, \"model.pt\"))\n  File \"/data/leuven/371/vsc37132/miniconda3/envs/qtype-eval/lib/python3.9/site-packages/torch/serialization.py\", line 857, in save\n    return\n  File \"/data/leuven/371/vsc37132/miniconda3/envs/qtype-eval/lib/python3.9/site-packages/torch/serialization.py\", line 690, in __exit__\n    self.file_like.write_end_of_file()\nRuntimeError: [enforce fail at inline_container.cc:603] . unexpected pos 1568281856 vs 1568281808\n\nDuring handling of the above exception, another exception occurred:\n\nTraceback (most recent call last):\n  File \"/data/leuven/371/vsc37132/miniconda3/envs/qtype-eval/lib/python3.9/logging/__init__.py\", line 1157, in close\n    self.flush()\n  File \"/data/leuven/371/vsc37132/miniconda3/envs/qtype-eval/lib/python3.9/logging/__init__.py\", line 1067, in flush\n    self.stream.flush()\nOSError: [Errno 122] Disk quota exceeded\n\nDuring handling of the above exception, another exception occurred:\n\nOSError: [Errno 122] Disk quota exceeded\n\nDuring handling of the above exception, another exception occurred:\n\nTraceback (most recent call last):\n  File \"/vsc-hard-mounts/leuven-data/371/vsc37132/qtype-eval/src/experiments/run_experiment.py\", line 210, in main\n    results = run_lm_experiment(cfg, task, task_type, submetric)\n  File \"/vsc-hard-mounts/leuven-data/371/vsc37132/qtype-eval/src/experiments/run_experiment.py\", line 432, in run_lm_experiment\n    wandb_run.finish()\n  File \"/data/leuven/371/vsc37132/miniconda3/envs/qtype-eval/lib/python3.9/site-packages/wandb/sdk/wandb_run.py\", line 387, in wrapper\n    return func(self, *args, **kwargs)\n  File \"/data/leuven/371/vsc37132/miniconda3/envs/qtype-eval/lib/python3.9/site-packages/wandb/sdk/wandb_run.py\", line 483, in wrapper\n    return func(self, *args, **kwargs)\n  File \"/data/leuven/371/vsc37132/miniconda3/envs/qtype-eval/lib/python3.9/site-packages/wandb/sdk/wandb_run.py\", line 425, in wrapper\n    return func(self, *args, **kwargs)\n  File \"/data/leuven/371/vsc37132/miniconda3/envs/qtype-eval/lib/python3.9/site-packages/wandb/sdk/wandb_run.py\", line 2182, in finish\n    return self._finish(exit_code)\n  File \"/data/leuven/371/vsc37132/miniconda3/envs/qtype-eval/lib/python3.9/site-packages/wandb/sdk/wandb_run.py\", line 387, in wrapper\n    return func(self, *args, **kwargs)\n  File \"/data/leuven/371/vsc37132/miniconda3/envs/qtype-eval/lib/python3.9/site-packages/wandb/sdk/wandb_run.py\", line 2210, in _finish\n    hook.call()\n  File \"/data/leuven/371/vsc37132/miniconda3/envs/qtype-eval/lib/python3.9/site-packages/wandb/sdk/wandb_init.py\", line 651, in dispose_handler\n    handler.close()\n  File \"/data/leuven/371/vsc37132/miniconda3/envs/qtype-eval/lib/python3.9/logging/__init__.py\", line 1162, in close\n    stream.close()\nOSError: [Errno 122] Disk quota exceeded\n",
  "task": "single_submetric",
  "task_type": "regression",
  "submetric": "avg_max_depth",
  "experiment_type": "lm_probe"
}